2017-10-17 11:15:25,963 [Thread-33:9620] [django.request:152] [base:get_response] [WARNING]- Not Found: /commissonList/
2017-10-17 11:19:55,766 [Thread-52:2092] [django.request:152] [base:get_response] [WARNING]- Not Found: /favicon.ico
2017-10-17 11:27:40,200 [Thread-36:6796] [django.request:152] [base:get_response] [WARNING]- Not Found: /favicon.ico
2017-10-17 11:27:43,546 [Thread-38:8652] [django.request:152] [base:get_response] [WARNING]- Not Found: /favicon.ico
2017-10-17 11:33:39,519 [Thread-2:10672] [django.request:152] [base:get_response] [WARNING]- Not Found: /
2017-10-17 11:33:40,111 [Thread-3:10580] [django.request:152] [base:get_response] [WARNING]- Not Found: /favicon.ico
2017-10-17 11:45:13,040 [Thread-45:5308] [django.request:152] [base:get_response] [WARNING]- Not Found: /get_db/
2017-10-17 11:45:17,282 [Thread-46:10076] [django.request:152] [base:get_response] [WARNING]- Not Found: /get_db/
2017-10-17 11:46:36,099 [Thread-47:10332] [django.request:152] [base:get_response] [WARNING]- Not Found: /get_db/
2017-10-17 11:46:45,706 [Thread-48:10120] [django.request:152] [base:get_response] [WARNING]- Not Found: /get_db/
2017-10-17 12:19:17,480 [Thread-49:5552] [django.request:152] [base:get_response] [WARNING]- Not Found: /get_db/
2017-10-17 14:49:12,401 [Thread-3:8396] [django.request:152] [base:get_response] [WARNING]- Not Found: /favicon.ico
2017-10-17 15:13:25,529 [Thread-2:8228] [django.request:135] [exception:handle_uncaught_exception] [ERROR]- Internal Server Error: /get_envs/
Traceback (most recent call last):
  File "C:\Python27\lib\site-packages\django\core\handlers\exception.py", line 41, in inner
    response = get_response(request)
  File "C:\Python27\lib\site-packages\django\core\handlers\base.py", line 187, in _get_response
    response = self.process_exception_by_middleware(e, request)
  File "C:\Python27\lib\site-packages\django\core\handlers\base.py", line 185, in _get_response
    response = wrapped_callback(request, *callback_args, **callback_kwargs)
  File "E:\apitestsys\apitest\views.py", line 82, in get_envs
    print envs['fields']
TypeError: string indices must be integers
2017-10-17 15:17:32,069 [Thread-2:8228] [django.request:135] [exception:handle_uncaught_exception] [ERROR]- Internal Server Error: /get_envs/
Traceback (most recent call last):
  File "C:\Python27\lib\site-packages\django\core\handlers\exception.py", line 41, in inner
    response = get_response(request)
  File "C:\Python27\lib\site-packages\django\core\handlers\base.py", line 187, in _get_response
    response = self.process_exception_by_middleware(e, request)
  File "C:\Python27\lib\site-packages\django\core\handlers\base.py", line 185, in _get_response
    response = wrapped_callback(request, *callback_args, **callback_kwargs)
  File "E:\apitestsys\apitest\views.py", line 81, in get_envs
    envs = query_json("Environment", {"project_id": project_id})
  File "E:\apitestsys\apitest\views.py", line 206, in query_json
    result.append(i.fields)
AttributeError: 'unicode' object has no attribute 'fields'
2017-10-17 15:41:40,733 [Thread-31:3436] [django.request:152] [base:get_response] [WARNING]- Not Found: /get_db/
2017-10-17 16:29:23,582 [Thread-2:8676] [django.request:135] [exception:handle_uncaught_exception] [ERROR]- Internal Server Error: /get_envs/
Traceback (most recent call last):
  File "C:\Python27\lib\site-packages\django\core\handlers\exception.py", line 41, in inner
    response = get_response(request)
  File "C:\Python27\lib\site-packages\django\core\handlers\base.py", line 187, in _get_response
    response = self.process_exception_by_middleware(e, request)
  File "C:\Python27\lib\site-packages\django\core\handlers\base.py", line 185, in _get_response
    response = wrapped_callback(request, *callback_args, **callback_kwargs)
  File "E:\apitestsys\apitest\views.py", line 83, in get_envs
    return JsonResponse({"status": "ok", "result": envs})
  File "C:\Python27\lib\site-packages\django\http\response.py", line 530, in __init__
    data = json.dumps(data, cls=encoder, **json_dumps_params)
  File "C:\Python27\lib\json\__init__.py", line 238, in dumps
    **kw).encode(obj)
  File "C:\Python27\lib\json\encoder.py", line 201, in encode
    chunks = self.iterencode(o, _one_shot=True)
  File "C:\Python27\lib\json\encoder.py", line 264, in iterencode
    return _iterencode(o, 0)
  File "C:\Python27\lib\site-packages\django\core\serializers\json.py", line 124, in default
    return super(DjangoJSONEncoder, self).default(o)
  File "C:\Python27\lib\json\encoder.py", line 178, in default
    raise TypeError(repr(o) + " is not JSON serializable")
TypeError: <QuerySet [<Environment: Environment object>, <Environment: Environment object>, <Environment: Environment object>, <Environment: Environment object>]> is not JSON serializable
2017-10-17 16:31:39,778 [Thread-2:6740] [django.request:135] [exception:handle_uncaught_exception] [ERROR]- Internal Server Error: /get_envs/
Traceback (most recent call last):
  File "C:\Python27\lib\site-packages\django\core\handlers\exception.py", line 41, in inner
    response = get_response(request)
  File "C:\Python27\lib\site-packages\django\core\handlers\base.py", line 187, in _get_response
    response = self.process_exception_by_middleware(e, request)
  File "C:\Python27\lib\site-packages\django\core\handlers\base.py", line 185, in _get_response
    response = wrapped_callback(request, *callback_args, **callback_kwargs)
  File "E:\apitestsys\apitest\views.py", line 82, in get_envs
    print i['project_id']
TypeError: 'Environment' object is not subscriptable
2017-10-17 16:31:55,048 [Thread-8:9420] [django.request:135] [exception:handle_uncaught_exception] [ERROR]- Internal Server Error: /get_envs/
Traceback (most recent call last):
  File "C:\Python27\lib\site-packages\django\core\handlers\exception.py", line 41, in inner
    response = get_response(request)
  File "C:\Python27\lib\site-packages\django\core\handlers\base.py", line 187, in _get_response
    response = self.process_exception_by_middleware(e, request)
  File "C:\Python27\lib\site-packages\django\core\handlers\base.py", line 185, in _get_response
    response = wrapped_callback(request, *callback_args, **callback_kwargs)
  File "E:\apitestsys\apitest\views.py", line 82, in get_envs
    print i['project_id']
TypeError: 'Environment' object is not subscriptable
2017-10-17 16:56:00,285 [Thread-2:10516] [django.request:135] [exception:handle_uncaught_exception] [ERROR]- Internal Server Error: /get_envs/
Traceback (most recent call last):
  File "C:\Python27\lib\site-packages\django\core\handlers\exception.py", line 41, in inner
    response = get_response(request)
  File "C:\Python27\lib\site-packages\django\core\handlers\base.py", line 187, in _get_response
    response = self.process_exception_by_middleware(e, request)
  File "C:\Python27\lib\site-packages\django\core\handlers\base.py", line 185, in _get_response
    response = wrapped_callback(request, *callback_args, **callback_kwargs)
  File "E:\apitestsys\apitest\views.py", line 89, in get_envs
    database = query_json("Database",{"project_env_id": id})
  File "E:\apitestsys\apitest\views.py", line 213, in query_json
    querySet = table.objects.filter(**filter)
  File "C:\Python27\lib\site-packages\django\db\models\manager.py", line 85, in manager_method
    return getattr(self.get_queryset(), name)(*args, **kwargs)
  File "C:\Python27\lib\site-packages\django\db\models\query.py", line 784, in filter
    return self._filter_or_exclude(False, *args, **kwargs)
  File "C:\Python27\lib\site-packages\django\db\models\query.py", line 802, in _filter_or_exclude
    clone.query.add_q(Q(*args, **kwargs))
  File "C:\Python27\lib\site-packages\django\db\models\sql\query.py", line 1250, in add_q
    clause, _ = self._add_q(q_object, self.used_aliases)
  File "C:\Python27\lib\site-packages\django\db\models\sql\query.py", line 1276, in _add_q
    allow_joins=allow_joins, split_subq=split_subq,
  File "C:\Python27\lib\site-packages\django\db\models\sql\query.py", line 1210, in build_filter
    condition = self.build_lookup(lookups, col, value)
  File "C:\Python27\lib\site-packages\django\db\models\sql\query.py", line 1104, in build_lookup
    return final_lookup(lhs, rhs)
  File "C:\Python27\lib\site-packages\django\db\models\lookups.py", line 24, in __init__
    self.rhs = self.get_prep_lookup()
  File "C:\Python27\lib\site-packages\django\db\models\lookups.py", line 74, in get_prep_lookup
    return self.lhs.output_field.get_prep_value(self.rhs)
  File "C:\Python27\lib\site-packages\django\db\models\fields\__init__.py", line 1853, in get_prep_value
    return int(value)
TypeError: int() argument must be a string or a number, not 'builtin_function_or_method'
2017-10-17 17:24:51,509 [Thread-2:11052] [django.request:135] [exception:handle_uncaught_exception] [ERROR]- Internal Server Error: /get_envs/
Traceback (most recent call last):
  File "C:\Python27\lib\site-packages\django\core\handlers\exception.py", line 41, in inner
    response = get_response(request)
  File "C:\Python27\lib\site-packages\django\core\handlers\base.py", line 187, in _get_response
    response = self.process_exception_by_middleware(e, request)
  File "C:\Python27\lib\site-packages\django\core\handlers\base.py", line 185, in _get_response
    response = wrapped_callback(request, *callback_args, **callback_kwargs)
  File "E:\apitestsys\apitest\views.py", line 92, in get_envs
    print result["database"]
KeyError: u'database'
2017-10-18 10:24:16,486 [Thread-8:8384] [django.request:135] [exception:handle_uncaught_exception] [ERROR]- Internal Server Error: /save_env/
Traceback (most recent call last):
  File "C:\Python27\lib\site-packages\django\core\handlers\exception.py", line 41, in inner
    response = get_response(request)
  File "C:\Python27\lib\site-packages\django\core\handlers\base.py", line 187, in _get_response
    response = self.process_exception_by_middleware(e, request)
  File "C:\Python27\lib\site-packages\django\core\handlers\base.py", line 185, in _get_response
    response = wrapped_callback(request, *callback_args, **callback_kwargs)
  File "E:\apitestsys\apitest\views.py", line 114, in save_env
    store_json("Environment", jsons_data)
  File "E:\apitestsys\apitest\views.py", line 209, in store_json
    table.objects.create(**jsondata)
  File "C:\Python27\lib\site-packages\django\db\models\manager.py", line 85, in manager_method
    return getattr(self.get_queryset(), name)(*args, **kwargs)
  File "C:\Python27\lib\site-packages\django\db\models\query.py", line 394, in create
    obj.save(force_insert=True, using=self.db)
  File "C:\Python27\lib\site-packages\django\db\models\base.py", line 807, in save
    force_update=force_update, update_fields=update_fields)
  File "C:\Python27\lib\site-packages\django\db\models\base.py", line 837, in save_base
    updated = self._save_table(raw, cls, force_insert, force_update, using, update_fields)
  File "C:\Python27\lib\site-packages\django\db\models\base.py", line 923, in _save_table
    result = self._do_insert(cls._base_manager, using, fields, update_pk, raw)
  File "C:\Python27\lib\site-packages\django\db\models\base.py", line 962, in _do_insert
    using=using, raw=raw)
  File "C:\Python27\lib\site-packages\django\db\models\manager.py", line 85, in manager_method
    return getattr(self.get_queryset(), name)(*args, **kwargs)
  File "C:\Python27\lib\site-packages\django\db\models\query.py", line 1076, in _insert
    return query.get_compiler(using=using).execute_sql(return_id)
  File "C:\Python27\lib\site-packages\django\db\models\sql\compiler.py", line 1107, in execute_sql
    cursor.execute(sql, params)
  File "C:\Python27\lib\site-packages\django\db\backends\utils.py", line 80, in execute
    return super(CursorDebugWrapper, self).execute(sql, params)
  File "C:\Python27\lib\site-packages\django\db\backends\utils.py", line 65, in execute
    return self.cursor.execute(sql, params)
  File "C:\Python27\lib\site-packages\django\db\utils.py", line 94, in __exit__
    six.reraise(dj_exc_type, dj_exc_value, traceback)
  File "C:\Python27\lib\site-packages\django\db\backends\utils.py", line 65, in execute
    return self.cursor.execute(sql, params)
  File "C:\Python27\lib\site-packages\django\db\backends\sqlite3\base.py", line 328, in execute
    return Database.Cursor.execute(self, query, params)
OperationalError: table apitest_environment has no column named data_base_id
2017-10-18 10:24:32,151 [Thread-9:8528] [django.request:135] [exception:handle_uncaught_exception] [ERROR]- Internal Server Error: /save_env/
Traceback (most recent call last):
  File "C:\Python27\lib\site-packages\django\core\handlers\exception.py", line 41, in inner
    response = get_response(request)
  File "C:\Python27\lib\site-packages\django\core\handlers\base.py", line 187, in _get_response
    response = self.process_exception_by_middleware(e, request)
  File "C:\Python27\lib\site-packages\django\core\handlers\base.py", line 185, in _get_response
    response = wrapped_callback(request, *callback_args, **callback_kwargs)
  File "E:\apitestsys\apitest\views.py", line 114, in save_env
    store_json("Environment", jsons_data)
  File "E:\apitestsys\apitest\views.py", line 209, in store_json
    table.objects.create(**jsondata)
  File "C:\Python27\lib\site-packages\django\db\models\manager.py", line 85, in manager_method
    return getattr(self.get_queryset(), name)(*args, **kwargs)
  File "C:\Python27\lib\site-packages\django\db\models\query.py", line 394, in create
    obj.save(force_insert=True, using=self.db)
  File "C:\Python27\lib\site-packages\django\db\models\base.py", line 807, in save
    force_update=force_update, update_fields=update_fields)
  File "C:\Python27\lib\site-packages\django\db\models\base.py", line 837, in save_base
    updated = self._save_table(raw, cls, force_insert, force_update, using, update_fields)
  File "C:\Python27\lib\site-packages\django\db\models\base.py", line 923, in _save_table
    result = self._do_insert(cls._base_manager, using, fields, update_pk, raw)
  File "C:\Python27\lib\site-packages\django\db\models\base.py", line 962, in _do_insert
    using=using, raw=raw)
  File "C:\Python27\lib\site-packages\django\db\models\manager.py", line 85, in manager_method
    return getattr(self.get_queryset(), name)(*args, **kwargs)
  File "C:\Python27\lib\site-packages\django\db\models\query.py", line 1076, in _insert
    return query.get_compiler(using=using).execute_sql(return_id)
  File "C:\Python27\lib\site-packages\django\db\models\sql\compiler.py", line 1107, in execute_sql
    cursor.execute(sql, params)
  File "C:\Python27\lib\site-packages\django\db\backends\utils.py", line 80, in execute
    return super(CursorDebugWrapper, self).execute(sql, params)
  File "C:\Python27\lib\site-packages\django\db\backends\utils.py", line 65, in execute
    return self.cursor.execute(sql, params)
  File "C:\Python27\lib\site-packages\django\db\utils.py", line 94, in __exit__
    six.reraise(dj_exc_type, dj_exc_value, traceback)
  File "C:\Python27\lib\site-packages\django\db\backends\utils.py", line 65, in execute
    return self.cursor.execute(sql, params)
  File "C:\Python27\lib\site-packages\django\db\backends\sqlite3\base.py", line 328, in execute
    return Database.Cursor.execute(self, query, params)
OperationalError: table apitest_environment has no column named data_base_id
2017-10-18 10:26:01,125 [Thread-2:8892] [django.request:135] [exception:handle_uncaught_exception] [ERROR]- Internal Server Error: /save_env/
Traceback (most recent call last):
  File "C:\Python27\lib\site-packages\django\core\handlers\exception.py", line 41, in inner
    response = get_response(request)
  File "C:\Python27\lib\site-packages\django\core\handlers\base.py", line 187, in _get_response
    response = self.process_exception_by_middleware(e, request)
  File "C:\Python27\lib\site-packages\django\core\handlers\base.py", line 185, in _get_response
    response = wrapped_callback(request, *callback_args, **callback_kwargs)
  File "E:\apitestsys\apitest\views.py", line 115, in save_env
    store_json("Environment", jsons_data)
  File "E:\apitestsys\apitest\views.py", line 210, in store_json
    table.objects.create(**jsondata)
  File "C:\Python27\lib\site-packages\django\db\models\manager.py", line 85, in manager_method
    return getattr(self.get_queryset(), name)(*args, **kwargs)
  File "C:\Python27\lib\site-packages\django\db\models\query.py", line 394, in create
    obj.save(force_insert=True, using=self.db)
  File "C:\Python27\lib\site-packages\django\db\models\base.py", line 807, in save
    force_update=force_update, update_fields=update_fields)
  File "C:\Python27\lib\site-packages\django\db\models\base.py", line 837, in save_base
    updated = self._save_table(raw, cls, force_insert, force_update, using, update_fields)
  File "C:\Python27\lib\site-packages\django\db\models\base.py", line 923, in _save_table
    result = self._do_insert(cls._base_manager, using, fields, update_pk, raw)
  File "C:\Python27\lib\site-packages\django\db\models\base.py", line 962, in _do_insert
    using=using, raw=raw)
  File "C:\Python27\lib\site-packages\django\db\models\manager.py", line 85, in manager_method
    return getattr(self.get_queryset(), name)(*args, **kwargs)
  File "C:\Python27\lib\site-packages\django\db\models\query.py", line 1076, in _insert
    return query.get_compiler(using=using).execute_sql(return_id)
  File "C:\Python27\lib\site-packages\django\db\models\sql\compiler.py", line 1107, in execute_sql
    cursor.execute(sql, params)
  File "C:\Python27\lib\site-packages\django\db\backends\utils.py", line 80, in execute
    return super(CursorDebugWrapper, self).execute(sql, params)
  File "C:\Python27\lib\site-packages\django\db\backends\utils.py", line 65, in execute
    return self.cursor.execute(sql, params)
  File "C:\Python27\lib\site-packages\django\db\utils.py", line 94, in __exit__
    six.reraise(dj_exc_type, dj_exc_value, traceback)
  File "C:\Python27\lib\site-packages\django\db\backends\utils.py", line 65, in execute
    return self.cursor.execute(sql, params)
  File "C:\Python27\lib\site-packages\django\db\backends\sqlite3\base.py", line 328, in execute
    return Database.Cursor.execute(self, query, params)
OperationalError: table apitest_environment has no column named data_base_id
2017-10-18 10:29:40,927 [Thread-3:7792] [django.request:135] [exception:handle_uncaught_exception] [ERROR]- Internal Server Error: /save_env/
Traceback (most recent call last):
  File "C:\Python27\lib\site-packages\django\core\handlers\exception.py", line 41, in inner
    response = get_response(request)
  File "C:\Python27\lib\site-packages\django\core\handlers\base.py", line 187, in _get_response
    response = self.process_exception_by_middleware(e, request)
  File "C:\Python27\lib\site-packages\django\core\handlers\base.py", line 185, in _get_response
    response = wrapped_callback(request, *callback_args, **callback_kwargs)
  File "E:\apitestsys\apitest\views.py", line 115, in save_env
    store_json("Environment", jsons_data)
  File "E:\apitestsys\apitest\views.py", line 210, in store_json
    table.objects.create(**jsondata)
  File "C:\Python27\lib\site-packages\django\db\models\manager.py", line 85, in manager_method
    return getattr(self.get_queryset(), name)(*args, **kwargs)
  File "C:\Python27\lib\site-packages\django\db\models\query.py", line 394, in create
    obj.save(force_insert=True, using=self.db)
  File "C:\Python27\lib\site-packages\django\db\models\base.py", line 807, in save
    force_update=force_update, update_fields=update_fields)
  File "C:\Python27\lib\site-packages\django\db\models\base.py", line 837, in save_base
    updated = self._save_table(raw, cls, force_insert, force_update, using, update_fields)
  File "C:\Python27\lib\site-packages\django\db\models\base.py", line 923, in _save_table
    result = self._do_insert(cls._base_manager, using, fields, update_pk, raw)
  File "C:\Python27\lib\site-packages\django\db\models\base.py", line 962, in _do_insert
    using=using, raw=raw)
  File "C:\Python27\lib\site-packages\django\db\models\manager.py", line 85, in manager_method
    return getattr(self.get_queryset(), name)(*args, **kwargs)
  File "C:\Python27\lib\site-packages\django\db\models\query.py", line 1076, in _insert
    return query.get_compiler(using=using).execute_sql(return_id)
  File "C:\Python27\lib\site-packages\django\db\models\sql\compiler.py", line 1107, in execute_sql
    cursor.execute(sql, params)
  File "C:\Python27\lib\site-packages\django\db\backends\utils.py", line 80, in execute
    return super(CursorDebugWrapper, self).execute(sql, params)
  File "C:\Python27\lib\site-packages\django\db\backends\utils.py", line 65, in execute
    return self.cursor.execute(sql, params)
  File "C:\Python27\lib\site-packages\django\db\utils.py", line 94, in __exit__
    six.reraise(dj_exc_type, dj_exc_value, traceback)
  File "C:\Python27\lib\site-packages\django\db\backends\utils.py", line 65, in execute
    return self.cursor.execute(sql, params)
  File "C:\Python27\lib\site-packages\django\db\backends\sqlite3\base.py", line 328, in execute
    return Database.Cursor.execute(self, query, params)
OperationalError: table apitest_environment has no column named data_base_id
2017-10-18 10:29:56,002 [Thread-7:8564] [django.request:135] [exception:handle_uncaught_exception] [ERROR]- Internal Server Error: /save_env/
Traceback (most recent call last):
  File "C:\Python27\lib\site-packages\django\core\handlers\exception.py", line 41, in inner
    response = get_response(request)
  File "C:\Python27\lib\site-packages\django\core\handlers\base.py", line 187, in _get_response
    response = self.process_exception_by_middleware(e, request)
  File "C:\Python27\lib\site-packages\django\core\handlers\base.py", line 185, in _get_response
    response = wrapped_callback(request, *callback_args, **callback_kwargs)
  File "E:\apitestsys\apitest\views.py", line 115, in save_env
    store_json("Environment", jsons_data)
  File "E:\apitestsys\apitest\views.py", line 210, in store_json
    table.objects.create(**jsondata)
  File "C:\Python27\lib\site-packages\django\db\models\manager.py", line 85, in manager_method
    return getattr(self.get_queryset(), name)(*args, **kwargs)
  File "C:\Python27\lib\site-packages\django\db\models\query.py", line 394, in create
    obj.save(force_insert=True, using=self.db)
  File "C:\Python27\lib\site-packages\django\db\models\base.py", line 807, in save
    force_update=force_update, update_fields=update_fields)
  File "C:\Python27\lib\site-packages\django\db\models\base.py", line 837, in save_base
    updated = self._save_table(raw, cls, force_insert, force_update, using, update_fields)
  File "C:\Python27\lib\site-packages\django\db\models\base.py", line 923, in _save_table
    result = self._do_insert(cls._base_manager, using, fields, update_pk, raw)
  File "C:\Python27\lib\site-packages\django\db\models\base.py", line 962, in _do_insert
    using=using, raw=raw)
  File "C:\Python27\lib\site-packages\django\db\models\manager.py", line 85, in manager_method
    return getattr(self.get_queryset(), name)(*args, **kwargs)
  File "C:\Python27\lib\site-packages\django\db\models\query.py", line 1076, in _insert
    return query.get_compiler(using=using).execute_sql(return_id)
  File "C:\Python27\lib\site-packages\django\db\models\sql\compiler.py", line 1107, in execute_sql
    cursor.execute(sql, params)
  File "C:\Python27\lib\site-packages\django\db\backends\utils.py", line 80, in execute
    return super(CursorDebugWrapper, self).execute(sql, params)
  File "C:\Python27\lib\site-packages\django\db\backends\utils.py", line 65, in execute
    return self.cursor.execute(sql, params)
  File "C:\Python27\lib\site-packages\django\db\utils.py", line 94, in __exit__
    six.reraise(dj_exc_type, dj_exc_value, traceback)
  File "C:\Python27\lib\site-packages\django\db\backends\utils.py", line 65, in execute
    return self.cursor.execute(sql, params)
  File "C:\Python27\lib\site-packages\django\db\backends\sqlite3\base.py", line 328, in execute
    return Database.Cursor.execute(self, query, params)
OperationalError: table apitest_environment has no column named data_base_id
2017-10-18 10:32:31,394 [Thread-2:8344] [django.request:135] [exception:handle_uncaught_exception] [ERROR]- Internal Server Error: /save_env/
Traceback (most recent call last):
  File "C:\Python27\lib\site-packages\django\core\handlers\exception.py", line 41, in inner
    response = get_response(request)
  File "C:\Python27\lib\site-packages\django\core\handlers\base.py", line 187, in _get_response
    response = self.process_exception_by_middleware(e, request)
  File "C:\Python27\lib\site-packages\django\core\handlers\base.py", line 185, in _get_response
    response = wrapped_callback(request, *callback_args, **callback_kwargs)
  File "E:\apitestsys\apitest\views.py", line 117, in save_env
    store_json("Environment", jsons_data)
  File "E:\apitestsys\apitest\views.py", line 212, in store_json
    table.objects.create(**jsondata)
  File "C:\Python27\lib\site-packages\django\db\models\manager.py", line 85, in manager_method
    return getattr(self.get_queryset(), name)(*args, **kwargs)
  File "C:\Python27\lib\site-packages\django\db\models\query.py", line 394, in create
    obj.save(force_insert=True, using=self.db)
  File "C:\Python27\lib\site-packages\django\db\models\base.py", line 807, in save
    force_update=force_update, update_fields=update_fields)
  File "C:\Python27\lib\site-packages\django\db\models\base.py", line 837, in save_base
    updated = self._save_table(raw, cls, force_insert, force_update, using, update_fields)
  File "C:\Python27\lib\site-packages\django\db\models\base.py", line 923, in _save_table
    result = self._do_insert(cls._base_manager, using, fields, update_pk, raw)
  File "C:\Python27\lib\site-packages\django\db\models\base.py", line 962, in _do_insert
    using=using, raw=raw)
  File "C:\Python27\lib\site-packages\django\db\models\manager.py", line 85, in manager_method
    return getattr(self.get_queryset(), name)(*args, **kwargs)
  File "C:\Python27\lib\site-packages\django\db\models\query.py", line 1076, in _insert
    return query.get_compiler(using=using).execute_sql(return_id)
  File "C:\Python27\lib\site-packages\django\db\models\sql\compiler.py", line 1107, in execute_sql
    cursor.execute(sql, params)
  File "C:\Python27\lib\site-packages\django\db\backends\utils.py", line 80, in execute
    return super(CursorDebugWrapper, self).execute(sql, params)
  File "C:\Python27\lib\site-packages\django\db\backends\utils.py", line 65, in execute
    return self.cursor.execute(sql, params)
  File "C:\Python27\lib\site-packages\django\db\utils.py", line 94, in __exit__
    six.reraise(dj_exc_type, dj_exc_value, traceback)
  File "C:\Python27\lib\site-packages\django\db\backends\utils.py", line 65, in execute
    return self.cursor.execute(sql, params)
  File "C:\Python27\lib\site-packages\django\db\backends\sqlite3\base.py", line 328, in execute
    return Database.Cursor.execute(self, query, params)
OperationalError: table apitest_environment has no column named data_base_id
2017-10-18 10:33:21,790 [Thread-2:8700] [django.request:135] [exception:handle_uncaught_exception] [ERROR]- Internal Server Error: /save_env/
Traceback (most recent call last):
  File "C:\Python27\lib\site-packages\django\core\handlers\exception.py", line 41, in inner
    response = get_response(request)
  File "C:\Python27\lib\site-packages\django\core\handlers\base.py", line 187, in _get_response
    response = self.process_exception_by_middleware(e, request)
  File "C:\Python27\lib\site-packages\django\core\handlers\base.py", line 185, in _get_response
    response = wrapped_callback(request, *callback_args, **callback_kwargs)
  File "E:\apitestsys\apitest\views.py", line 117, in save_env
    store_json("Environment", jsons_data)
  File "E:\apitestsys\apitest\views.py", line 212, in store_json
    table.objects.create(**jsondata)
  File "C:\Python27\lib\site-packages\django\db\models\manager.py", line 85, in manager_method
    return getattr(self.get_queryset(), name)(*args, **kwargs)
  File "C:\Python27\lib\site-packages\django\db\models\query.py", line 394, in create
    obj.save(force_insert=True, using=self.db)
  File "C:\Python27\lib\site-packages\django\db\models\base.py", line 807, in save
    force_update=force_update, update_fields=update_fields)
  File "C:\Python27\lib\site-packages\django\db\models\base.py", line 837, in save_base
    updated = self._save_table(raw, cls, force_insert, force_update, using, update_fields)
  File "C:\Python27\lib\site-packages\django\db\models\base.py", line 923, in _save_table
    result = self._do_insert(cls._base_manager, using, fields, update_pk, raw)
  File "C:\Python27\lib\site-packages\django\db\models\base.py", line 962, in _do_insert
    using=using, raw=raw)
  File "C:\Python27\lib\site-packages\django\db\models\manager.py", line 85, in manager_method
    return getattr(self.get_queryset(), name)(*args, **kwargs)
  File "C:\Python27\lib\site-packages\django\db\models\query.py", line 1076, in _insert
    return query.get_compiler(using=using).execute_sql(return_id)
  File "C:\Python27\lib\site-packages\django\db\models\sql\compiler.py", line 1107, in execute_sql
    cursor.execute(sql, params)
  File "C:\Python27\lib\site-packages\django\db\backends\utils.py", line 80, in execute
    return super(CursorDebugWrapper, self).execute(sql, params)
  File "C:\Python27\lib\site-packages\django\db\backends\utils.py", line 65, in execute
    return self.cursor.execute(sql, params)
  File "C:\Python27\lib\site-packages\django\db\utils.py", line 94, in __exit__
    six.reraise(dj_exc_type, dj_exc_value, traceback)
  File "C:\Python27\lib\site-packages\django\db\backends\utils.py", line 65, in execute
    return self.cursor.execute(sql, params)
  File "C:\Python27\lib\site-packages\django\db\backends\sqlite3\base.py", line 328, in execute
    return Database.Cursor.execute(self, query, params)
OperationalError: table apitest_environment has no column named data_base_id
2017-10-18 10:33:41,721 [Thread-2:7684] [django.request:135] [exception:handle_uncaught_exception] [ERROR]- Internal Server Error: /save_env/
Traceback (most recent call last):
  File "C:\Python27\lib\site-packages\django\core\handlers\exception.py", line 41, in inner
    response = get_response(request)
  File "C:\Python27\lib\site-packages\django\core\handlers\base.py", line 187, in _get_response
    response = self.process_exception_by_middleware(e, request)
  File "C:\Python27\lib\site-packages\django\core\handlers\base.py", line 185, in _get_response
    response = wrapped_callback(request, *callback_args, **callback_kwargs)
  File "E:\apitestsys\apitest\views.py", line 117, in save_env
    store_json("Environment", jsons_data)
  File "E:\apitestsys\apitest\views.py", line 212, in store_json
    table.objects.create(**jsondata)
  File "C:\Python27\lib\site-packages\django\db\models\manager.py", line 85, in manager_method
    return getattr(self.get_queryset(), name)(*args, **kwargs)
  File "C:\Python27\lib\site-packages\django\db\models\query.py", line 394, in create
    obj.save(force_insert=True, using=self.db)
  File "C:\Python27\lib\site-packages\django\db\models\base.py", line 807, in save
    force_update=force_update, update_fields=update_fields)
  File "C:\Python27\lib\site-packages\django\db\models\base.py", line 837, in save_base
    updated = self._save_table(raw, cls, force_insert, force_update, using, update_fields)
  File "C:\Python27\lib\site-packages\django\db\models\base.py", line 923, in _save_table
    result = self._do_insert(cls._base_manager, using, fields, update_pk, raw)
  File "C:\Python27\lib\site-packages\django\db\models\base.py", line 962, in _do_insert
    using=using, raw=raw)
  File "C:\Python27\lib\site-packages\django\db\models\manager.py", line 85, in manager_method
    return getattr(self.get_queryset(), name)(*args, **kwargs)
  File "C:\Python27\lib\site-packages\django\db\models\query.py", line 1076, in _insert
    return query.get_compiler(using=using).execute_sql(return_id)
  File "C:\Python27\lib\site-packages\django\db\models\sql\compiler.py", line 1107, in execute_sql
    cursor.execute(sql, params)
  File "C:\Python27\lib\site-packages\django\db\backends\utils.py", line 80, in execute
    return super(CursorDebugWrapper, self).execute(sql, params)
  File "C:\Python27\lib\site-packages\django\db\backends\utils.py", line 65, in execute
    return self.cursor.execute(sql, params)
  File "C:\Python27\lib\site-packages\django\db\utils.py", line 94, in __exit__
    six.reraise(dj_exc_type, dj_exc_value, traceback)
  File "C:\Python27\lib\site-packages\django\db\backends\utils.py", line 65, in execute
    return self.cursor.execute(sql, params)
  File "C:\Python27\lib\site-packages\django\db\backends\sqlite3\base.py", line 328, in execute
    return Database.Cursor.execute(self, query, params)
OperationalError: table apitest_environment has no column named data_base_id
2017-10-18 10:35:04,480 [Thread-2:2804] [django.request:135] [exception:handle_uncaught_exception] [ERROR]- Internal Server Error: /save_env/
Traceback (most recent call last):
  File "C:\Python27\lib\site-packages\django\core\handlers\exception.py", line 41, in inner
    response = get_response(request)
  File "C:\Python27\lib\site-packages\django\core\handlers\base.py", line 187, in _get_response
    response = self.process_exception_by_middleware(e, request)
  File "C:\Python27\lib\site-packages\django\core\handlers\base.py", line 185, in _get_response
    response = wrapped_callback(request, *callback_args, **callback_kwargs)
  File "E:\apitestsys\apitest\views.py", line 117, in save_env
    store_json("Environment", jsons_data)
  File "E:\apitestsys\apitest\views.py", line 209, in store_json
    table.objects.create(**jsondata)
  File "C:\Python27\lib\site-packages\django\db\models\manager.py", line 85, in manager_method
    return getattr(self.get_queryset(), name)(*args, **kwargs)
  File "C:\Python27\lib\site-packages\django\db\models\query.py", line 394, in create
    obj.save(force_insert=True, using=self.db)
  File "C:\Python27\lib\site-packages\django\db\models\base.py", line 807, in save
    force_update=force_update, update_fields=update_fields)
  File "C:\Python27\lib\site-packages\django\db\models\base.py", line 837, in save_base
    updated = self._save_table(raw, cls, force_insert, force_update, using, update_fields)
  File "C:\Python27\lib\site-packages\django\db\models\base.py", line 923, in _save_table
    result = self._do_insert(cls._base_manager, using, fields, update_pk, raw)
  File "C:\Python27\lib\site-packages\django\db\models\base.py", line 962, in _do_insert
    using=using, raw=raw)
  File "C:\Python27\lib\site-packages\django\db\models\manager.py", line 85, in manager_method
    return getattr(self.get_queryset(), name)(*args, **kwargs)
  File "C:\Python27\lib\site-packages\django\db\models\query.py", line 1076, in _insert
    return query.get_compiler(using=using).execute_sql(return_id)
  File "C:\Python27\lib\site-packages\django\db\models\sql\compiler.py", line 1107, in execute_sql
    cursor.execute(sql, params)
  File "C:\Python27\lib\site-packages\django\db\backends\utils.py", line 80, in execute
    return super(CursorDebugWrapper, self).execute(sql, params)
  File "C:\Python27\lib\site-packages\django\db\backends\utils.py", line 65, in execute
    return self.cursor.execute(sql, params)
  File "C:\Python27\lib\site-packages\django\db\utils.py", line 94, in __exit__
    six.reraise(dj_exc_type, dj_exc_value, traceback)
  File "C:\Python27\lib\site-packages\django\db\backends\utils.py", line 65, in execute
    return self.cursor.execute(sql, params)
  File "C:\Python27\lib\site-packages\django\db\backends\sqlite3\base.py", line 328, in execute
    return Database.Cursor.execute(self, query, params)
OperationalError: table apitest_environment has no column named data_base_id
2017-10-18 10:38:53,151 [Thread-2:5096] [django.request:135] [exception:handle_uncaught_exception] [ERROR]- Internal Server Error: /save_env/
Traceback (most recent call last):
  File "C:\Python27\lib\site-packages\django\core\handlers\exception.py", line 41, in inner
    response = get_response(request)
  File "C:\Python27\lib\site-packages\django\core\handlers\base.py", line 187, in _get_response
    response = self.process_exception_by_middleware(e, request)
  File "C:\Python27\lib\site-packages\django\core\handlers\base.py", line 185, in _get_response
    response = wrapped_callback(request, *callback_args, **callback_kwargs)
  File "E:\apitestsys\apitest\views.py", line 117, in save_env
    store_json("Environment", jsons_data)
  File "E:\apitestsys\apitest\views.py", line 209, in store_json
    table.objects.create(**jsondata)
  File "C:\Python27\lib\site-packages\django\db\models\manager.py", line 85, in manager_method
    return getattr(self.get_queryset(), name)(*args, **kwargs)
  File "C:\Python27\lib\site-packages\django\db\models\query.py", line 394, in create
    obj.save(force_insert=True, using=self.db)
  File "C:\Python27\lib\site-packages\django\db\models\base.py", line 807, in save
    force_update=force_update, update_fields=update_fields)
  File "C:\Python27\lib\site-packages\django\db\models\base.py", line 837, in save_base
    updated = self._save_table(raw, cls, force_insert, force_update, using, update_fields)
  File "C:\Python27\lib\site-packages\django\db\models\base.py", line 923, in _save_table
    result = self._do_insert(cls._base_manager, using, fields, update_pk, raw)
  File "C:\Python27\lib\site-packages\django\db\models\base.py", line 962, in _do_insert
    using=using, raw=raw)
  File "C:\Python27\lib\site-packages\django\db\models\manager.py", line 85, in manager_method
    return getattr(self.get_queryset(), name)(*args, **kwargs)
  File "C:\Python27\lib\site-packages\django\db\models\query.py", line 1076, in _insert
    return query.get_compiler(using=using).execute_sql(return_id)
  File "C:\Python27\lib\site-packages\django\db\models\sql\compiler.py", line 1107, in execute_sql
    cursor.execute(sql, params)
  File "C:\Python27\lib\site-packages\django\db\backends\utils.py", line 80, in execute
    return super(CursorDebugWrapper, self).execute(sql, params)
  File "C:\Python27\lib\site-packages\django\db\backends\utils.py", line 65, in execute
    return self.cursor.execute(sql, params)
  File "C:\Python27\lib\site-packages\django\db\utils.py", line 94, in __exit__
    six.reraise(dj_exc_type, dj_exc_value, traceback)
  File "C:\Python27\lib\site-packages\django\db\backends\utils.py", line 65, in execute
    return self.cursor.execute(sql, params)
  File "C:\Python27\lib\site-packages\django\db\backends\sqlite3\base.py", line 328, in execute
    return Database.Cursor.execute(self, query, params)
OperationalError: table apitest_environment has no column named data_base_id
2017-10-18 10:40:09,226 [Thread-10:9076] [django.request:135] [exception:handle_uncaught_exception] [ERROR]- Internal Server Error: /save_env/
Traceback (most recent call last):
  File "C:\Python27\lib\site-packages\django\core\handlers\exception.py", line 41, in inner
    response = get_response(request)
  File "C:\Python27\lib\site-packages\django\core\handlers\base.py", line 187, in _get_response
    response = self.process_exception_by_middleware(e, request)
  File "C:\Python27\lib\site-packages\django\core\handlers\base.py", line 185, in _get_response
    response = wrapped_callback(request, *callback_args, **callback_kwargs)
  File "E:/apitestsys\apitest\views.py", line 117, in save_env
    store_json("Environment", jsons_data)
  File "E:/apitestsys\apitest\views.py", line 209, in store_json
    table.objects.create(**jsondata)
  File "C:\Python27\lib\site-packages\django\db\models\manager.py", line 85, in manager_method
    return getattr(self.get_queryset(), name)(*args, **kwargs)
  File "C:\Python27\lib\site-packages\django\db\models\query.py", line 394, in create
    obj.save(force_insert=True, using=self.db)
  File "C:\Python27\lib\site-packages\django\db\models\base.py", line 807, in save
    force_update=force_update, update_fields=update_fields)
  File "C:\Python27\lib\site-packages\django\db\models\base.py", line 837, in save_base
    updated = self._save_table(raw, cls, force_insert, force_update, using, update_fields)
  File "C:\Python27\lib\site-packages\django\db\models\base.py", line 923, in _save_table
    result = self._do_insert(cls._base_manager, using, fields, update_pk, raw)
  File "C:\Python27\lib\site-packages\django\db\models\base.py", line 962, in _do_insert
    using=using, raw=raw)
  File "C:\Python27\lib\site-packages\django\db\models\manager.py", line 85, in manager_method
    return getattr(self.get_queryset(), name)(*args, **kwargs)
  File "C:\Python27\lib\site-packages\django\db\models\query.py", line 1076, in _insert
    return query.get_compiler(using=using).execute_sql(return_id)
  File "C:\Python27\lib\site-packages\django\db\models\sql\compiler.py", line 1107, in execute_sql
    cursor.execute(sql, params)
  File "C:\Python27\lib\site-packages\django\db\backends\utils.py", line 80, in execute
    return super(CursorDebugWrapper, self).execute(sql, params)
  File "C:\Python27\lib\site-packages\django\db\backends\utils.py", line 65, in execute
    return self.cursor.execute(sql, params)
  File "C:\Python27\lib\site-packages\django\db\utils.py", line 94, in __exit__
    six.reraise(dj_exc_type, dj_exc_value, traceback)
  File "C:\Python27\lib\site-packages\django\db\backends\utils.py", line 65, in execute
    return self.cursor.execute(sql, params)
  File "C:\Python27\lib\site-packages\django\db\backends\sqlite3\base.py", line 328, in execute
    return Database.Cursor.execute(self, query, params)
OperationalError: table apitest_environment has no column named data_base_id
2017-10-18 10:42:27,369 [Thread-11:3408] [django.request:135] [exception:handle_uncaught_exception] [ERROR]- Internal Server Error: /save_env/
Traceback (most recent call last):
  File "C:\Python27\lib\site-packages\django\core\handlers\exception.py", line 41, in inner
    response = get_response(request)
  File "C:\Python27\lib\site-packages\django\core\handlers\base.py", line 187, in _get_response
    response = self.process_exception_by_middleware(e, request)
  File "C:\Python27\lib\site-packages\django\core\handlers\base.py", line 185, in _get_response
    response = wrapped_callback(request, *callback_args, **callback_kwargs)
  File "E:/apitestsys\apitest\views.py", line 117, in save_env
    store_json("Environment", jsons_data)
  File "E:/apitestsys\apitest\views.py", line 209, in store_json
    table.objects.create(**jsondata)
  File "C:\Python27\lib\site-packages\django\db\models\manager.py", line 85, in manager_method
    return getattr(self.get_queryset(), name)(*args, **kwargs)
  File "C:\Python27\lib\site-packages\django\db\models\query.py", line 394, in create
    obj.save(force_insert=True, using=self.db)
  File "C:\Python27\lib\site-packages\django\db\models\base.py", line 807, in save
    force_update=force_update, update_fields=update_fields)
  File "C:\Python27\lib\site-packages\django\db\models\base.py", line 837, in save_base
    updated = self._save_table(raw, cls, force_insert, force_update, using, update_fields)
  File "C:\Python27\lib\site-packages\django\db\models\base.py", line 923, in _save_table
    result = self._do_insert(cls._base_manager, using, fields, update_pk, raw)
  File "C:\Python27\lib\site-packages\django\db\models\base.py", line 962, in _do_insert
    using=using, raw=raw)
  File "C:\Python27\lib\site-packages\django\db\models\manager.py", line 85, in manager_method
    return getattr(self.get_queryset(), name)(*args, **kwargs)
  File "C:\Python27\lib\site-packages\django\db\models\query.py", line 1076, in _insert
    return query.get_compiler(using=using).execute_sql(return_id)
  File "C:\Python27\lib\site-packages\django\db\models\sql\compiler.py", line 1107, in execute_sql
    cursor.execute(sql, params)
  File "C:\Python27\lib\site-packages\django\db\backends\utils.py", line 80, in execute
    return super(CursorDebugWrapper, self).execute(sql, params)
  File "C:\Python27\lib\site-packages\django\db\backends\utils.py", line 65, in execute
    return self.cursor.execute(sql, params)
  File "C:\Python27\lib\site-packages\django\db\utils.py", line 94, in __exit__
    six.reraise(dj_exc_type, dj_exc_value, traceback)
  File "C:\Python27\lib\site-packages\django\db\backends\utils.py", line 65, in execute
    return self.cursor.execute(sql, params)
  File "C:\Python27\lib\site-packages\django\db\backends\sqlite3\base.py", line 328, in execute
    return Database.Cursor.execute(self, query, params)
IntegrityError: apitest_environment.checked may not be NULL
2017-10-18 10:43:51,328 [Thread-2:6004] [django.request:135] [exception:handle_uncaught_exception] [ERROR]- Internal Server Error: /save_env/
Traceback (most recent call last):
  File "C:\Python27\lib\site-packages\django\core\handlers\exception.py", line 41, in inner
    response = get_response(request)
  File "C:\Python27\lib\site-packages\django\core\handlers\base.py", line 187, in _get_response
    response = self.process_exception_by_middleware(e, request)
  File "C:\Python27\lib\site-packages\django\core\handlers\base.py", line 185, in _get_response
    response = wrapped_callback(request, *callback_args, **callback_kwargs)
  File "E:\apitestsys\apitest\views.py", line 117, in save_env
    store_json("Environment", jsons_data)
  File "E:\apitestsys\apitest\views.py", line 209, in store_json
    table.objects.create(**jsondata)
  File "C:\Python27\lib\site-packages\django\db\models\manager.py", line 85, in manager_method
    return getattr(self.get_queryset(), name)(*args, **kwargs)
  File "C:\Python27\lib\site-packages\django\db\models\query.py", line 394, in create
    obj.save(force_insert=True, using=self.db)
  File "C:\Python27\lib\site-packages\django\db\models\base.py", line 807, in save
    force_update=force_update, update_fields=update_fields)
  File "C:\Python27\lib\site-packages\django\db\models\base.py", line 837, in save_base
    updated = self._save_table(raw, cls, force_insert, force_update, using, update_fields)
  File "C:\Python27\lib\site-packages\django\db\models\base.py", line 923, in _save_table
    result = self._do_insert(cls._base_manager, using, fields, update_pk, raw)
  File "C:\Python27\lib\site-packages\django\db\models\base.py", line 962, in _do_insert
    using=using, raw=raw)
  File "C:\Python27\lib\site-packages\django\db\models\manager.py", line 85, in manager_method
    return getattr(self.get_queryset(), name)(*args, **kwargs)
  File "C:\Python27\lib\site-packages\django\db\models\query.py", line 1076, in _insert
    return query.get_compiler(using=using).execute_sql(return_id)
  File "C:\Python27\lib\site-packages\django\db\models\sql\compiler.py", line 1107, in execute_sql
    cursor.execute(sql, params)
  File "C:\Python27\lib\site-packages\django\db\backends\utils.py", line 80, in execute
    return super(CursorDebugWrapper, self).execute(sql, params)
  File "C:\Python27\lib\site-packages\django\db\backends\utils.py", line 65, in execute
    return self.cursor.execute(sql, params)
  File "C:\Python27\lib\site-packages\django\db\utils.py", line 94, in __exit__
    six.reraise(dj_exc_type, dj_exc_value, traceback)
  File "C:\Python27\lib\site-packages\django\db\backends\utils.py", line 65, in execute
    return self.cursor.execute(sql, params)
  File "C:\Python27\lib\site-packages\django\db\backends\sqlite3\base.py", line 328, in execute
    return Database.Cursor.execute(self, query, params)
IntegrityError: apitest_environment.checked may not be NULL
2017-10-18 14:30:32,246 [Thread-2:10832] [django.request:152] [base:get_response] [WARNING]- Not Found: /commissonList/
2017-10-18 14:30:32,447 [Thread-3:7644] [django.request:152] [base:get_response] [WARNING]- Not Found: /favicon.ico
2017-10-18 14:30:39,161 [Thread-4:12168] [django.request:152] [base:get_response] [WARNING]- Not Found: /commissonList/
2017-10-18 14:35:39,359 [Thread-18:2848] [django.request:152] [base:get_response] [WARNING]- Not Found: /commissonList/
2017-10-18 17:30:37,642 [Thread-7:9184] [django.request:135] [exception:handle_uncaught_exception] [ERROR]- Internal Server Error: /save_email/
Traceback (most recent call last):
  File "C:\Python27\lib\site-packages\django\core\handlers\exception.py", line 41, in inner
    response = get_response(request)
  File "C:\Python27\lib\site-packages\django\core\handlers\base.py", line 187, in _get_response
    response = self.process_exception_by_middleware(e, request)
  File "C:\Python27\lib\site-packages\django\core\handlers\base.py", line 185, in _get_response
    response = wrapped_callback(request, *callback_args, **callback_kwargs)
  File "E:\apitestsys\apitest\views.py", line 148, in save_email
    store_json("Email", jsons_data)
  File "E:\apitestsys\apitest\views.py", line 210, in store_json
    table.objects.create(**jsondata)
  File "C:\Python27\lib\site-packages\django\db\models\manager.py", line 85, in manager_method
    return getattr(self.get_queryset(), name)(*args, **kwargs)
  File "C:\Python27\lib\site-packages\django\db\models\query.py", line 394, in create
    obj.save(force_insert=True, using=self.db)
  File "C:\Python27\lib\site-packages\django\db\models\base.py", line 807, in save
    force_update=force_update, update_fields=update_fields)
  File "C:\Python27\lib\site-packages\django\db\models\base.py", line 837, in save_base
    updated = self._save_table(raw, cls, force_insert, force_update, using, update_fields)
  File "C:\Python27\lib\site-packages\django\db\models\base.py", line 923, in _save_table
    result = self._do_insert(cls._base_manager, using, fields, update_pk, raw)
  File "C:\Python27\lib\site-packages\django\db\models\base.py", line 962, in _do_insert
    using=using, raw=raw)
  File "C:\Python27\lib\site-packages\django\db\models\manager.py", line 85, in manager_method
    return getattr(self.get_queryset(), name)(*args, **kwargs)
  File "C:\Python27\lib\site-packages\django\db\models\query.py", line 1076, in _insert
    return query.get_compiler(using=using).execute_sql(return_id)
  File "C:\Python27\lib\site-packages\django\db\models\sql\compiler.py", line 1107, in execute_sql
    cursor.execute(sql, params)
  File "C:\Python27\lib\site-packages\django\db\backends\utils.py", line 80, in execute
    return super(CursorDebugWrapper, self).execute(sql, params)
  File "C:\Python27\lib\site-packages\django\db\backends\utils.py", line 65, in execute
    return self.cursor.execute(sql, params)
  File "C:\Python27\lib\site-packages\django\db\utils.py", line 94, in __exit__
    six.reraise(dj_exc_type, dj_exc_value, traceback)
  File "C:\Python27\lib\site-packages\django\db\backends\utils.py", line 65, in execute
    return self.cursor.execute(sql, params)
  File "C:\Python27\lib\site-packages\django\db\backends\sqlite3\base.py", line 328, in execute
    return Database.Cursor.execute(self, query, params)
OperationalError: table apitest_email has no column named username
2017-10-18 17:30:44,339 [Thread-8:7888] [django.request:135] [exception:handle_uncaught_exception] [ERROR]- Internal Server Error: /save_email/
Traceback (most recent call last):
  File "C:\Python27\lib\site-packages\django\core\handlers\exception.py", line 41, in inner
    response = get_response(request)
  File "C:\Python27\lib\site-packages\django\core\handlers\base.py", line 187, in _get_response
    response = self.process_exception_by_middleware(e, request)
  File "C:\Python27\lib\site-packages\django\core\handlers\base.py", line 185, in _get_response
    response = wrapped_callback(request, *callback_args, **callback_kwargs)
  File "E:\apitestsys\apitest\views.py", line 148, in save_email
    store_json("Email", jsons_data)
  File "E:\apitestsys\apitest\views.py", line 210, in store_json
    table.objects.create(**jsondata)
  File "C:\Python27\lib\site-packages\django\db\models\manager.py", line 85, in manager_method
    return getattr(self.get_queryset(), name)(*args, **kwargs)
  File "C:\Python27\lib\site-packages\django\db\models\query.py", line 394, in create
    obj.save(force_insert=True, using=self.db)
  File "C:\Python27\lib\site-packages\django\db\models\base.py", line 807, in save
    force_update=force_update, update_fields=update_fields)
  File "C:\Python27\lib\site-packages\django\db\models\base.py", line 837, in save_base
    updated = self._save_table(raw, cls, force_insert, force_update, using, update_fields)
  File "C:\Python27\lib\site-packages\django\db\models\base.py", line 923, in _save_table
    result = self._do_insert(cls._base_manager, using, fields, update_pk, raw)
  File "C:\Python27\lib\site-packages\django\db\models\base.py", line 962, in _do_insert
    using=using, raw=raw)
  File "C:\Python27\lib\site-packages\django\db\models\manager.py", line 85, in manager_method
    return getattr(self.get_queryset(), name)(*args, **kwargs)
  File "C:\Python27\lib\site-packages\django\db\models\query.py", line 1076, in _insert
    return query.get_compiler(using=using).execute_sql(return_id)
  File "C:\Python27\lib\site-packages\django\db\models\sql\compiler.py", line 1107, in execute_sql
    cursor.execute(sql, params)
  File "C:\Python27\lib\site-packages\django\db\backends\utils.py", line 80, in execute
    return super(CursorDebugWrapper, self).execute(sql, params)
  File "C:\Python27\lib\site-packages\django\db\backends\utils.py", line 65, in execute
    return self.cursor.execute(sql, params)
  File "C:\Python27\lib\site-packages\django\db\utils.py", line 94, in __exit__
    six.reraise(dj_exc_type, dj_exc_value, traceback)
  File "C:\Python27\lib\site-packages\django\db\backends\utils.py", line 65, in execute
    return self.cursor.execute(sql, params)
  File "C:\Python27\lib\site-packages\django\db\backends\sqlite3\base.py", line 328, in execute
    return Database.Cursor.execute(self, query, params)
OperationalError: table apitest_email has no column named username
2017-10-18 17:55:01,644 [Thread-2:9596] [django.request:135] [exception:handle_uncaught_exception] [ERROR]- Internal Server Error: /save_email/
Traceback (most recent call last):
  File "C:\Python27\lib\site-packages\django\core\handlers\exception.py", line 41, in inner
    response = get_response(request)
  File "C:\Python27\lib\site-packages\django\core\handlers\base.py", line 187, in _get_response
    response = self.process_exception_by_middleware(e, request)
  File "C:\Python27\lib\site-packages\django\core\handlers\base.py", line 185, in _get_response
    response = wrapped_callback(request, *callback_args, **callback_kwargs)
  File "E:\apitestsys\apitest\views.py", line 148, in save_email
    store_json("Email", jsons_data)
  File "E:\apitestsys\apitest\views.py", line 210, in store_json
    table.objects.create(**jsondata)
  File "C:\Python27\lib\site-packages\django\db\models\manager.py", line 85, in manager_method
    return getattr(self.get_queryset(), name)(*args, **kwargs)
  File "C:\Python27\lib\site-packages\django\db\models\query.py", line 394, in create
    obj.save(force_insert=True, using=self.db)
  File "C:\Python27\lib\site-packages\django\db\models\base.py", line 807, in save
    force_update=force_update, update_fields=update_fields)
  File "C:\Python27\lib\site-packages\django\db\models\base.py", line 837, in save_base
    updated = self._save_table(raw, cls, force_insert, force_update, using, update_fields)
  File "C:\Python27\lib\site-packages\django\db\models\base.py", line 923, in _save_table
    result = self._do_insert(cls._base_manager, using, fields, update_pk, raw)
  File "C:\Python27\lib\site-packages\django\db\models\base.py", line 962, in _do_insert
    using=using, raw=raw)
  File "C:\Python27\lib\site-packages\django\db\models\manager.py", line 85, in manager_method
    return getattr(self.get_queryset(), name)(*args, **kwargs)
  File "C:\Python27\lib\site-packages\django\db\models\query.py", line 1076, in _insert
    return query.get_compiler(using=using).execute_sql(return_id)
  File "C:\Python27\lib\site-packages\django\db\models\sql\compiler.py", line 1107, in execute_sql
    cursor.execute(sql, params)
  File "C:\Python27\lib\site-packages\django\db\backends\utils.py", line 80, in execute
    return super(CursorDebugWrapper, self).execute(sql, params)
  File "C:\Python27\lib\site-packages\django\db\backends\utils.py", line 65, in execute
    return self.cursor.execute(sql, params)
  File "C:\Python27\lib\site-packages\django\db\utils.py", line 94, in __exit__
    six.reraise(dj_exc_type, dj_exc_value, traceback)
  File "C:\Python27\lib\site-packages\django\db\backends\utils.py", line 65, in execute
    return self.cursor.execute(sql, params)
  File "C:\Python27\lib\site-packages\django\db\backends\sqlite3\base.py", line 328, in execute
    return Database.Cursor.execute(self, query, params)
OperationalError: no such table: apitest_email
2017-10-18 18:06:51,592 [Thread-4:9924] [django.request:152] [base:get_response] [WARNING]- Not Found: /favicon.ico
2017-10-19 09:35:23,240 [Thread-8:7272] [django.request:135] [exception:handle_uncaught_exception] [ERROR]- Internal Server Error: /save_email/
Traceback (most recent call last):
  File "C:\Python27\lib\site-packages\django\core\handlers\exception.py", line 41, in inner
    response = get_response(request)
  File "C:\Python27\lib\site-packages\django\core\handlers\base.py", line 187, in _get_response
    response = self.process_exception_by_middleware(e, request)
  File "C:\Python27\lib\site-packages\django\core\handlers\base.py", line 185, in _get_response
    response = wrapped_callback(request, *callback_args, **callback_kwargs)
  File "E:\apitestsys\apitest\views.py", line 136, in save_email
    req = json.loads(request.body)
  File "C:\Python27\lib\json\__init__.py", line 310, in loads
    return _default_decoder.decode(s)
  File "C:\Python27\lib\json\decoder.py", line 346, in decode
    obj, end = self.raw_decode(s, idx=_w(s, 0).end())
  File "C:\Python27\lib\json\decoder.py", line 364, in raw_decode
    raise ValueError("No JSON object could be decoded")
ValueError: No JSON object could be decoded
2017-10-19 09:35:30,752 [Thread-9:7344] [django.request:135] [exception:handle_uncaught_exception] [ERROR]- Internal Server Error: /save_email/
Traceback (most recent call last):
  File "C:\Python27\lib\site-packages\django\core\handlers\exception.py", line 41, in inner
    response = get_response(request)
  File "C:\Python27\lib\site-packages\django\core\handlers\base.py", line 187, in _get_response
    response = self.process_exception_by_middleware(e, request)
  File "C:\Python27\lib\site-packages\django\core\handlers\base.py", line 185, in _get_response
    response = wrapped_callback(request, *callback_args, **callback_kwargs)
  File "E:\apitestsys\apitest\views.py", line 136, in save_email
    req = json.loads(request.body)
  File "C:\Python27\lib\json\__init__.py", line 310, in loads
    return _default_decoder.decode(s)
  File "C:\Python27\lib\json\decoder.py", line 346, in decode
    obj, end = self.raw_decode(s, idx=_w(s, 0).end())
  File "C:\Python27\lib\json\decoder.py", line 364, in raw_decode
    raise ValueError("No JSON object could be decoded")
ValueError: No JSON object could be decoded
2017-10-19 09:37:38,727 [Thread-2:2756] [django.request:135] [exception:handle_uncaught_exception] [ERROR]- Internal Server Error: /save_email/
Traceback (most recent call last):
  File "C:\Python27\lib\site-packages\django\core\handlers\exception.py", line 41, in inner
    response = get_response(request)
  File "C:\Python27\lib\site-packages\django\core\handlers\base.py", line 187, in _get_response
    response = self.process_exception_by_middleware(e, request)
  File "C:\Python27\lib\site-packages\django\core\handlers\base.py", line 185, in _get_response
    response = wrapped_callback(request, *callback_args, **callback_kwargs)
  File "E:\apitestsys\apitest\views.py", line 135, in save_email
    req = json.loads(request.body)
  File "C:\Python27\lib\json\__init__.py", line 310, in loads
    return _default_decoder.decode(s)
  File "C:\Python27\lib\json\decoder.py", line 346, in decode
    obj, end = self.raw_decode(s, idx=_w(s, 0).end())
  File "C:\Python27\lib\json\decoder.py", line 364, in raw_decode
    raise ValueError("No JSON object could be decoded")
ValueError: No JSON object could be decoded
2017-10-19 09:59:39,002 [Thread-2:4284] [django.request:135] [exception:handle_uncaught_exception] [ERROR]- Internal Server Error: /save_email/
Traceback (most recent call last):
  File "C:\Python27\lib\site-packages\django\core\handlers\exception.py", line 41, in inner
    response = get_response(request)
  File "C:\Python27\lib\site-packages\django\core\handlers\base.py", line 187, in _get_response
    response = self.process_exception_by_middleware(e, request)
  File "C:\Python27\lib\site-packages\django\core\handlers\base.py", line 185, in _get_response
    response = wrapped_callback(request, *callback_args, **callback_kwargs)
  File "E:\apitestsys\apitest\views.py", line 136, in save_email
    json = request.POST['data']
  File "C:\Python27\lib\site-packages\django\utils\datastructures.py", line 85, in __getitem__
    raise MultiValueDictKeyError(repr(key))
MultiValueDictKeyError: "u'data'"
2017-10-19 13:01:34,931 [Thread-58:11132] [django.request:152] [base:get_response] [WARNING]- Not Found: /get_db/
2017-10-27 11:01:30,380 [Thread-32:1336] [django.request:152] [base:get_response] [WARNING]- Not Found: /commissonList/
2017-10-27 11:01:30,543 [Thread-33:3960] [django.request:152] [base:get_response] [WARNING]- Not Found: /favicon.ico
2017-10-27 11:17:51,566 [Thread-44:3256] [django.request:152] [base:get_response] [WARNING]- Not Found: /commissonList/
2017-10-27 16:07:17,575 [Thread-71:9756] [django.request:152] [base:get_response] [WARNING]- Not Found: /commissonList/
2017-10-27 16:08:28,325 [Thread-82:9960] [django.request:152] [base:get_response] [WARNING]- Not Found: /get_db/
2017-10-27 16:08:32,732 [Thread-83:9968] [django.request:152] [base:get_response] [WARNING]- Not Found: /get_db/
2017-11-02 10:20:57,457 [Thread-29:2268] [django.request:135] [exception:handle_uncaught_exception] [ERROR]- Internal Server Error: /get_project/
Traceback (most recent call last):
  File "C:\Python27\lib\site-packages\django\core\handlers\exception.py", line 41, in inner
    response = get_response(request)
  File "C:\Python27\lib\site-packages\django\core\handlers\base.py", line 187, in _get_response
    response = self.process_exception_by_middleware(e, request)
  File "C:\Python27\lib\site-packages\django\core\handlers\base.py", line 185, in _get_response
    response = wrapped_callback(request, *callback_args, **callback_kwargs)
  File "E:\apitestsys\apitest\views.py", line 122, in get_project_base
    return JsonResponse({"status": "ok", "result": result})
  File "C:\Python27\lib\site-packages\django\http\response.py", line 530, in __init__
    data = json.dumps(data, cls=encoder, **json_dumps_params)
  File "C:\Python27\lib\json\__init__.py", line 238, in dumps
    **kw).encode(obj)
  File "C:\Python27\lib\json\encoder.py", line 201, in encode
    chunks = self.iterencode(o, _one_shot=True)
  File "C:\Python27\lib\json\encoder.py", line 264, in iterencode
    return _iterencode(o, 0)
  File "C:\Python27\lib\site-packages\django\core\serializers\json.py", line 124, in default
    return super(DjangoJSONEncoder, self).default(o)
  File "C:\Python27\lib\json\encoder.py", line 178, in default
    raise TypeError(repr(o) + " is not JSON serializable")
TypeError: <QuerySet [<Project: Project object>]> is not JSON serializable
2017-11-02 10:21:48,497 [Thread-56:3856] [django.request:135] [exception:handle_uncaught_exception] [ERROR]- Internal Server Error: /get_project/
Traceback (most recent call last):
  File "C:\Python27\lib\site-packages\django\core\handlers\exception.py", line 41, in inner
    response = get_response(request)
  File "C:\Python27\lib\site-packages\django\core\handlers\base.py", line 187, in _get_response
    response = self.process_exception_by_middleware(e, request)
  File "C:\Python27\lib\site-packages\django\core\handlers\base.py", line 185, in _get_response
    response = wrapped_callback(request, *callback_args, **callback_kwargs)
  File "E:\apitestsys\apitest\views.py", line 122, in get_project_base
    return JsonResponse({"status": "ok", "result": result})
  File "C:\Python27\lib\site-packages\django\http\response.py", line 530, in __init__
    data = json.dumps(data, cls=encoder, **json_dumps_params)
  File "C:\Python27\lib\json\__init__.py", line 238, in dumps
    **kw).encode(obj)
  File "C:\Python27\lib\json\encoder.py", line 201, in encode
    chunks = self.iterencode(o, _one_shot=True)
  File "C:\Python27\lib\json\encoder.py", line 264, in iterencode
    return _iterencode(o, 0)
  File "C:\Python27\lib\site-packages\django\core\serializers\json.py", line 124, in default
    return super(DjangoJSONEncoder, self).default(o)
  File "C:\Python27\lib\json\encoder.py", line 178, in default
    raise TypeError(repr(o) + " is not JSON serializable")
TypeError: <QuerySet [<Project: Project object>]> is not JSON serializable
2017-11-02 10:33:58,739 [Thread-28:10236] [django.request:135] [exception:handle_uncaught_exception] [ERROR]- Internal Server Error: /get_project/
Traceback (most recent call last):
  File "C:\Python27\lib\site-packages\django\core\handlers\exception.py", line 41, in inner
    response = get_response(request)
  File "C:\Python27\lib\site-packages\django\core\handlers\base.py", line 187, in _get_response
    response = self.process_exception_by_middleware(e, request)
  File "C:\Python27\lib\site-packages\django\core\handlers\base.py", line 185, in _get_response
    response = wrapped_callback(request, *callback_args, **callback_kwargs)
  File "E:\apitestsys\apitest\views.py", line 122, in get_project_base
    result = dict(project_name=i.name, interface_type=i.type, project_desc=i.desc)
AttributeError: 'Project' object has no attribute 'type'
2017-11-02 10:34:26,851 [Thread-54:2160] [django.request:135] [exception:handle_uncaught_exception] [ERROR]- Internal Server Error: /get_project/
Traceback (most recent call last):
  File "C:\Python27\lib\site-packages\django\core\handlers\exception.py", line 41, in inner
    response = get_response(request)
  File "C:\Python27\lib\site-packages\django\core\handlers\base.py", line 187, in _get_response
    response = self.process_exception_by_middleware(e, request)
  File "C:\Python27\lib\site-packages\django\core\handlers\base.py", line 185, in _get_response
    response = wrapped_callback(request, *callback_args, **callback_kwargs)
  File "E:\apitestsys\apitest\views.py", line 122, in get_project_base
    result = dict(project_name=i.name, interface_type=i.type, project_desc=i.desc)
AttributeError: 'Project' object has no attribute 'type'
